[2023-12-12 19:25:01,900] INFO _log() L187  [33mPress CTRL+C to quit[0m - call_trace=C:\Users\Paula\AppData\Local\Programs\Python\Python311\Lib\site-packages\werkzeug\_internal.py L187 
[2023-12-12 19:25:01,903] INFO _log() L187   * Restarting with stat - call_trace=C:\Users\Paula\AppData\Local\Programs\Python\Python311\Lib\site-packages\werkzeug\_internal.py L187 
[2023-12-12 19:25:45,783] INFO _log() L187   * Detected change in 'C:\\Users\\Paula\\Documents\\CURSOS\\Pos Eng Software\\Sprint 4\\MVP\\codigos\\mvp_sleep_health\\api\\model\\modelo.py', reloading - call_trace=C:\Users\Paula\AppData\Local\Programs\Python\Python311\Lib\site-packages\werkzeug\_internal.py L187 
[2023-12-12 19:25:45,906] INFO _log() L187   * Restarting with stat - call_trace=C:\Users\Paula\AppData\Local\Programs\Python\Python311\Lib\site-packages\werkzeug\_internal.py L187 
[2023-12-12 19:25:49,710] INFO _log() L187   * Detected change in 'C:\\Users\\Paula\\Documents\\CURSOS\\Pos Eng Software\\Sprint 4\\MVP\\codigos\\mvp_sleep_health\\api\\model\\modelo.py', reloading - call_trace=C:\Users\Paula\AppData\Local\Programs\Python\Python311\Lib\site-packages\werkzeug\_internal.py L187 
[2023-12-12 19:25:49,846] INFO _log() L187   * Restarting with stat - call_trace=C:\Users\Paula\AppData\Local\Programs\Python\Python311\Lib\site-packages\werkzeug\_internal.py L187 
[2023-12-12 19:27:06,285] INFO _log() L187  [31m[1mWARNING: This is a development server. Do not use it in a production deployment. Use a production WSGI server instead.[0m
 * Running on http://127.0.0.1:5000 - call_trace=C:\Users\Paula\AppData\Local\Programs\Python\Python311\Lib\site-packages\werkzeug\_internal.py L187 
[2023-12-12 19:27:06,286] INFO _log() L187  [33mPress CTRL+C to quit[0m - call_trace=C:\Users\Paula\AppData\Local\Programs\Python\Python311\Lib\site-packages\werkzeug\_internal.py L187 
[2023-12-12 19:27:06,288] INFO _log() L187   * Restarting with stat - call_trace=C:\Users\Paula\AppData\Local\Programs\Python\Python311\Lib\site-packages\werkzeug\_internal.py L187 
[2023-12-12 19:27:25,506] INFO _log() L187  127.0.0.1 - - [12/Dec/2023 19:27:25] "GET /pessoas HTTP/1.1" 200 - - call_trace=C:\Users\Paula\AppData\Local\Programs\Python\Python311\Lib\site-packages\werkzeug\_internal.py L187 
[2023-12-12 19:29:10,370] INFO _log() L187  127.0.0.1 - - [12/Dec/2023 19:29:10] "GET /pessoas?person_id=8 HTTP/1.1" 200 - - call_trace=C:\Users\Paula\AppData\Local\Programs\Python\Python311\Lib\site-packages\werkzeug\_internal.py L187 
[2023-12-12 19:29:10,379] ERROR _finalize_fairy() L781  Exception during reset or similar - call_trace=C:\Users\Paula\AppData\Local\Programs\Python\Python311\Lib\site-packages\sqlalchemy\pool\base.py L781 
Traceback (most recent call last):
  File "C:\Users\Paula\AppData\Local\Programs\Python\Python311\Lib\site-packages\sqlalchemy\pool\base.py", line 753, in _finalize_fairy
    fairy._reset(pool)
  File "C:\Users\Paula\AppData\Local\Programs\Python\Python311\Lib\site-packages\sqlalchemy\pool\base.py", line 1004, in _reset
    pool._dialect.do_rollback(self)
  File "C:\Users\Paula\AppData\Local\Programs\Python\Python311\Lib\site-packages\sqlalchemy\engine\default.py", line 683, in do_rollback
    dbapi_connection.rollback()
sqlite3.ProgrammingError: SQLite objects created in a thread can only be used in that same thread. The object was created in thread id 2428 and this is thread id 22912.
[2023-12-12 19:29:10,382] ERROR _close_connection() L259  Exception closing connection <sqlite3.Connection object at 0x0000025D07F8C310> - call_trace=C:\Users\Paula\AppData\Local\Programs\Python\Python311\Lib\site-packages\sqlalchemy\pool\base.py L259 
Traceback (most recent call last):
  File "C:\Users\Paula\AppData\Local\Programs\Python\Python311\Lib\site-packages\sqlalchemy\pool\base.py", line 753, in _finalize_fairy
    fairy._reset(pool)
  File "C:\Users\Paula\AppData\Local\Programs\Python\Python311\Lib\site-packages\sqlalchemy\pool\base.py", line 1004, in _reset
    pool._dialect.do_rollback(self)
  File "C:\Users\Paula\AppData\Local\Programs\Python\Python311\Lib\site-packages\sqlalchemy\engine\default.py", line 683, in do_rollback
    dbapi_connection.rollback()
sqlite3.ProgrammingError: SQLite objects created in a thread can only be used in that same thread. The object was created in thread id 2428 and this is thread id 22912.

During handling of the above exception, another exception occurred:

Traceback (most recent call last):
  File "C:\Users\Paula\AppData\Local\Programs\Python\Python311\Lib\site-packages\sqlalchemy\pool\base.py", line 255, in _close_connection
    self._dialect.do_terminate(connection)
  File "C:\Users\Paula\AppData\Local\Programs\Python\Python311\Lib\site-packages\sqlalchemy\engine\default.py", line 689, in do_terminate
    self.do_close(dbapi_connection)
  File "C:\Users\Paula\AppData\Local\Programs\Python\Python311\Lib\site-packages\sqlalchemy\engine\default.py", line 692, in do_close
    dbapi_connection.close()
sqlite3.ProgrammingError: SQLite objects created in a thread can only be used in that same thread. The object was created in thread id 2428 and this is thread id 22912.
[2023-12-12 19:29:10,432] ERROR _finalize_fairy() L781  Exception during reset or similar - call_trace=C:\Users\Paula\AppData\Local\Programs\Python\Python311\Lib\site-packages\sqlalchemy\pool\base.py L781 
Traceback (most recent call last):
  File "C:\Users\Paula\AppData\Local\Programs\Python\Python311\Lib\site-packages\sqlalchemy\pool\base.py", line 753, in _finalize_fairy
    fairy._reset(pool)
  File "C:\Users\Paula\AppData\Local\Programs\Python\Python311\Lib\site-packages\sqlalchemy\pool\base.py", line 1004, in _reset
    pool._dialect.do_rollback(self)
  File "C:\Users\Paula\AppData\Local\Programs\Python\Python311\Lib\site-packages\sqlalchemy\engine\default.py", line 683, in do_rollback
    dbapi_connection.rollback()
sqlite3.ProgrammingError: SQLite objects created in a thread can only be used in that same thread. The object was created in thread id 6108 and this is thread id 22912.
[2023-12-12 19:29:10,435] ERROR _close_connection() L259  Exception closing connection <sqlite3.Connection object at 0x0000025D080464D0> - call_trace=C:\Users\Paula\AppData\Local\Programs\Python\Python311\Lib\site-packages\sqlalchemy\pool\base.py L259 
Traceback (most recent call last):
  File "C:\Users\Paula\AppData\Local\Programs\Python\Python311\Lib\site-packages\sqlalchemy\pool\base.py", line 753, in _finalize_fairy
    fairy._reset(pool)
  File "C:\Users\Paula\AppData\Local\Programs\Python\Python311\Lib\site-packages\sqlalchemy\pool\base.py", line 1004, in _reset
    pool._dialect.do_rollback(self)
  File "C:\Users\Paula\AppData\Local\Programs\Python\Python311\Lib\site-packages\sqlalchemy\engine\default.py", line 683, in do_rollback
    dbapi_connection.rollback()
sqlite3.ProgrammingError: SQLite objects created in a thread can only be used in that same thread. The object was created in thread id 6108 and this is thread id 22912.

During handling of the above exception, another exception occurred:

Traceback (most recent call last):
  File "C:\Users\Paula\AppData\Local\Programs\Python\Python311\Lib\site-packages\sqlalchemy\pool\base.py", line 255, in _close_connection
    self._dialect.do_terminate(connection)
  File "C:\Users\Paula\AppData\Local\Programs\Python\Python311\Lib\site-packages\sqlalchemy\engine\default.py", line 689, in do_terminate
    self.do_close(dbapi_connection)
  File "C:\Users\Paula\AppData\Local\Programs\Python\Python311\Lib\site-packages\sqlalchemy\engine\default.py", line 692, in do_close
    dbapi_connection.close()
sqlite3.ProgrammingError: SQLite objects created in a thread can only be used in that same thread. The object was created in thread id 6108 and this is thread id 22912.
[2023-12-12 19:29:11,023] INFO preditor() L50   ================ diagnosis[0] ============ : '0.0' - call_trace=C:\Users\Paula\Documents\CURSOS\Pos Eng Software\Sprint 4\MVP\codigos\mvp_sleep_health\api\model\modelo.py L50  
[2023-12-12 19:29:11,024] INFO predict() L111  Adicionando pessoa de número: '8' - call_trace=C:\Users\Paula\Documents\CURSOS\Pos Eng Software\Sprint 4\MVP\codigos\mvp_sleep_health\api\app.py L111 
[2023-12-12 19:29:11,044] INFO _log() L187  127.0.0.1 - - [12/Dec/2023 19:29:11] "POST /pessoa HTTP/1.1" 200 - - call_trace=C:\Users\Paula\AppData\Local\Programs\Python\Python311\Lib\site-packages\werkzeug\_internal.py L187 
[2023-12-12 19:29:17,361] INFO _log() L187  127.0.0.1 - - [12/Dec/2023 19:29:17] "GET /pessoas HTTP/1.1" 200 - - call_trace=C:\Users\Paula\AppData\Local\Programs\Python\Python311\Lib\site-packages\werkzeug\_internal.py L187 
[2023-12-12 19:30:38,774] INFO _log() L187  127.0.0.1 - - [12/Dec/2023 19:30:38] "GET /pessoas HTTP/1.1" 200 - - call_trace=C:\Users\Paula\AppData\Local\Programs\Python\Python311\Lib\site-packages\werkzeug\_internal.py L187 
[2023-12-12 19:30:58,317] INFO _log() L187  127.0.0.1 - - [12/Dec/2023 19:30:58] "OPTIONS /pessoa?person_id=8 HTTP/1.1" 200 - - call_trace=C:\Users\Paula\AppData\Local\Programs\Python\Python311\Lib\site-packages\werkzeug\_internal.py L187 
[2023-12-12 19:30:58,323] INFO delete_pessoa() L190  Deletando dados sobre pessoa - call_trace=C:\Users\Paula\Documents\CURSOS\Pos Eng Software\Sprint 4\MVP\codigos\mvp_sleep_health\api\app.py L190 
[2023-12-12 19:30:58,324] INFO delete_pessoa() L192  Deletando dados sobre pessoa #8 - call_trace=C:\Users\Paula\Documents\CURSOS\Pos Eng Software\Sprint 4\MVP\codigos\mvp_sleep_health\api\app.py L192 
[2023-12-12 19:30:58,342] INFO _log() L187  127.0.0.1 - - [12/Dec/2023 19:30:58] "DELETE /pessoa?person_id=8 HTTP/1.1" 200 - - call_trace=C:\Users\Paula\AppData\Local\Programs\Python\Python311\Lib\site-packages\werkzeug\_internal.py L187 
