[2023-12-12 19:00:16,927] INFO _log() L187  [31m[1mWARNING: This is a development server. Do not use it in a production deployment. Use a production WSGI server instead.[0m
 * Running on http://127.0.0.1:5000 - call_trace=C:\Users\Paula\AppData\Local\Programs\Python\Python311\Lib\site-packages\werkzeug\_internal.py L187 
[2023-12-12 19:00:16,931] INFO _log() L187  [33mPress CTRL+C to quit[0m - call_trace=C:\Users\Paula\AppData\Local\Programs\Python\Python311\Lib\site-packages\werkzeug\_internal.py L187 
[2023-12-12 19:00:16,933] INFO _log() L187   * Restarting with stat - call_trace=C:\Users\Paula\AppData\Local\Programs\Python\Python311\Lib\site-packages\werkzeug\_internal.py L187 
[2023-12-12 19:00:21,774] INFO _log() L187  127.0.0.1 - - [12/Dec/2023 19:00:21] "GET /pessoas HTTP/1.1" 200 - - call_trace=C:\Users\Paula\AppData\Local\Programs\Python\Python311\Lib\site-packages\werkzeug\_internal.py L187 
[2023-12-12 19:02:52,588] INFO _log() L187  127.0.0.1 - - [12/Dec/2023 19:02:52] "GET /pessoas?person_id=5 HTTP/1.1" 200 - - call_trace=C:\Users\Paula\AppData\Local\Programs\Python\Python311\Lib\site-packages\werkzeug\_internal.py L187 
[2023-12-12 19:02:52,598] ERROR _finalize_fairy() L781  Exception during reset or similar - call_trace=C:\Users\Paula\AppData\Local\Programs\Python\Python311\Lib\site-packages\sqlalchemy\pool\base.py L781 
Traceback (most recent call last):
  File "C:\Users\Paula\AppData\Local\Programs\Python\Python311\Lib\site-packages\sqlalchemy\pool\base.py", line 753, in _finalize_fairy
    fairy._reset(pool)
  File "C:\Users\Paula\AppData\Local\Programs\Python\Python311\Lib\site-packages\sqlalchemy\pool\base.py", line 1004, in _reset
    pool._dialect.do_rollback(self)
  File "C:\Users\Paula\AppData\Local\Programs\Python\Python311\Lib\site-packages\sqlalchemy\engine\default.py", line 683, in do_rollback
    dbapi_connection.rollback()
sqlite3.ProgrammingError: SQLite objects created in a thread can only be used in that same thread. The object was created in thread id 26860 and this is thread id 25200.
[2023-12-12 19:02:52,600] ERROR _close_connection() L259  Exception closing connection <sqlite3.Connection object at 0x000001A8FFA2C400> - call_trace=C:\Users\Paula\AppData\Local\Programs\Python\Python311\Lib\site-packages\sqlalchemy\pool\base.py L259 
Traceback (most recent call last):
  File "C:\Users\Paula\AppData\Local\Programs\Python\Python311\Lib\site-packages\sqlalchemy\pool\base.py", line 753, in _finalize_fairy
    fairy._reset(pool)
  File "C:\Users\Paula\AppData\Local\Programs\Python\Python311\Lib\site-packages\sqlalchemy\pool\base.py", line 1004, in _reset
    pool._dialect.do_rollback(self)
  File "C:\Users\Paula\AppData\Local\Programs\Python\Python311\Lib\site-packages\sqlalchemy\engine\default.py", line 683, in do_rollback
    dbapi_connection.rollback()
sqlite3.ProgrammingError: SQLite objects created in a thread can only be used in that same thread. The object was created in thread id 26860 and this is thread id 25200.

During handling of the above exception, another exception occurred:

Traceback (most recent call last):
  File "C:\Users\Paula\AppData\Local\Programs\Python\Python311\Lib\site-packages\sqlalchemy\pool\base.py", line 255, in _close_connection
    self._dialect.do_terminate(connection)
  File "C:\Users\Paula\AppData\Local\Programs\Python\Python311\Lib\site-packages\sqlalchemy\engine\default.py", line 689, in do_terminate
    self.do_close(dbapi_connection)
  File "C:\Users\Paula\AppData\Local\Programs\Python\Python311\Lib\site-packages\sqlalchemy\engine\default.py", line 692, in do_close
    dbapi_connection.close()
sqlite3.ProgrammingError: SQLite objects created in a thread can only be used in that same thread. The object was created in thread id 26860 and this is thread id 25200.
[2023-12-12 19:02:52,646] ERROR _finalize_fairy() L781  Exception during reset or similar - call_trace=C:\Users\Paula\AppData\Local\Programs\Python\Python311\Lib\site-packages\sqlalchemy\pool\base.py L781 
Traceback (most recent call last):
  File "C:\Users\Paula\AppData\Local\Programs\Python\Python311\Lib\site-packages\sqlalchemy\pool\base.py", line 753, in _finalize_fairy
    fairy._reset(pool)
  File "C:\Users\Paula\AppData\Local\Programs\Python\Python311\Lib\site-packages\sqlalchemy\pool\base.py", line 1004, in _reset
    pool._dialect.do_rollback(self)
  File "C:\Users\Paula\AppData\Local\Programs\Python\Python311\Lib\site-packages\sqlalchemy\engine\default.py", line 683, in do_rollback
    dbapi_connection.rollback()
sqlite3.ProgrammingError: SQLite objects created in a thread can only be used in that same thread. The object was created in thread id 4128 and this is thread id 25200.
[2023-12-12 19:02:52,649] ERROR _close_connection() L259  Exception closing connection <sqlite3.Connection object at 0x000001A8FFAE24D0> - call_trace=C:\Users\Paula\AppData\Local\Programs\Python\Python311\Lib\site-packages\sqlalchemy\pool\base.py L259 
Traceback (most recent call last):
  File "C:\Users\Paula\AppData\Local\Programs\Python\Python311\Lib\site-packages\sqlalchemy\pool\base.py", line 753, in _finalize_fairy
    fairy._reset(pool)
  File "C:\Users\Paula\AppData\Local\Programs\Python\Python311\Lib\site-packages\sqlalchemy\pool\base.py", line 1004, in _reset
    pool._dialect.do_rollback(self)
  File "C:\Users\Paula\AppData\Local\Programs\Python\Python311\Lib\site-packages\sqlalchemy\engine\default.py", line 683, in do_rollback
    dbapi_connection.rollback()
sqlite3.ProgrammingError: SQLite objects created in a thread can only be used in that same thread. The object was created in thread id 4128 and this is thread id 25200.

During handling of the above exception, another exception occurred:

Traceback (most recent call last):
  File "C:\Users\Paula\AppData\Local\Programs\Python\Python311\Lib\site-packages\sqlalchemy\pool\base.py", line 255, in _close_connection
    self._dialect.do_terminate(connection)
  File "C:\Users\Paula\AppData\Local\Programs\Python\Python311\Lib\site-packages\sqlalchemy\engine\default.py", line 689, in do_terminate
    self.do_close(dbapi_connection)
  File "C:\Users\Paula\AppData\Local\Programs\Python\Python311\Lib\site-packages\sqlalchemy\engine\default.py", line 692, in do_close
    dbapi_connection.close()
sqlite3.ProgrammingError: SQLite objects created in a thread can only be used in that same thread. The object was created in thread id 4128 and this is thread id 25200.
[2023-12-12 19:02:53,210] INFO preditor() L50   ================ diagnosis[0] ============ : '1.0' - call_trace=C:\Users\Paula\Documents\CURSOS\Pos Eng Software\Sprint 4\MVP\codigos\mvp_sleep_health\api\model\modelo.py L50  
[2023-12-12 19:02:53,211] INFO predict() L111  Adicionando pessoa de número: '5' - call_trace=C:\Users\Paula\Documents\CURSOS\Pos Eng Software\Sprint 4\MVP\codigos\mvp_sleep_health\api\app.py L111 
[2023-12-12 19:02:53,234] INFO _log() L187  127.0.0.1 - - [12/Dec/2023 19:02:53] "POST /pessoa HTTP/1.1" 200 - - call_trace=C:\Users\Paula\AppData\Local\Programs\Python\Python311\Lib\site-packages\werkzeug\_internal.py L187 
[2023-12-12 19:03:01,237] INFO _log() L187  127.0.0.1 - - [12/Dec/2023 19:03:01] "GET /pessoas HTTP/1.1" 200 - - call_trace=C:\Users\Paula\AppData\Local\Programs\Python\Python311\Lib\site-packages\werkzeug\_internal.py L187 
[2023-12-12 19:03:43,194] ERROR _finalize_fairy() L781  Exception during reset or similar - call_trace=C:\Users\Paula\AppData\Local\Programs\Python\Python311\Lib\site-packages\sqlalchemy\pool\base.py L781 
Traceback (most recent call last):
  File "C:\Users\Paula\AppData\Local\Programs\Python\Python311\Lib\site-packages\sqlalchemy\pool\base.py", line 753, in _finalize_fairy
    fairy._reset(pool)
  File "C:\Users\Paula\AppData\Local\Programs\Python\Python311\Lib\site-packages\sqlalchemy\pool\base.py", line 1004, in _reset
    pool._dialect.do_rollback(self)
  File "C:\Users\Paula\AppData\Local\Programs\Python\Python311\Lib\site-packages\sqlalchemy\engine\default.py", line 683, in do_rollback
    dbapi_connection.rollback()
sqlite3.ProgrammingError: SQLite objects created in a thread can only be used in that same thread. The object was created in thread id 13764 and this is thread id 26952.
[2023-12-12 19:03:43,209] ERROR _finalize_fairy() L781  Exception during reset or similar - call_trace=C:\Users\Paula\AppData\Local\Programs\Python\Python311\Lib\site-packages\sqlalchemy\pool\base.py L781 
Traceback (most recent call last):
  File "C:\Users\Paula\AppData\Local\Programs\Python\Python311\Lib\site-packages\sqlalchemy\pool\base.py", line 753, in _finalize_fairy
    fairy._reset(pool)
  File "C:\Users\Paula\AppData\Local\Programs\Python\Python311\Lib\site-packages\sqlalchemy\pool\base.py", line 1004, in _reset
    pool._dialect.do_rollback(self)
  File "C:\Users\Paula\AppData\Local\Programs\Python\Python311\Lib\site-packages\sqlalchemy\engine\default.py", line 683, in do_rollback
    dbapi_connection.rollback()
sqlite3.ProgrammingError: SQLite objects created in a thread can only be used in that same thread. The object was created in thread id 25200 and this is thread id 26952.
[2023-12-12 19:05:39,617] INFO _log() L187  [31m[1mWARNING: This is a development server. Do not use it in a production deployment. Use a production WSGI server instead.[0m
 * Running on http://127.0.0.1:5000 - call_trace=C:\Users\Paula\AppData\Local\Programs\Python\Python311\Lib\site-packages\werkzeug\_internal.py L187 
[2023-12-12 19:05:39,617] INFO _log() L187  [33mPress CTRL+C to quit[0m - call_trace=C:\Users\Paula\AppData\Local\Programs\Python\Python311\Lib\site-packages\werkzeug\_internal.py L187 
[2023-12-12 19:05:39,619] INFO _log() L187   * Restarting with stat - call_trace=C:\Users\Paula\AppData\Local\Programs\Python\Python311\Lib\site-packages\werkzeug\_internal.py L187 
