[2023-12-11 22:28:29,672] INFO _log() L187  [31m[1mWARNING: This is a development server. Do not use it in a production deployment. Use a production WSGI server instead.[0m
 * Running on http://127.0.0.1:5000 - call_trace=C:\Users\Paula\AppData\Local\Programs\Python\Python311\Lib\site-packages\werkzeug\_internal.py L187 
[2023-12-11 22:28:29,672] INFO _log() L187  [33mPress CTRL+C to quit[0m - call_trace=C:\Users\Paula\AppData\Local\Programs\Python\Python311\Lib\site-packages\werkzeug\_internal.py L187 
[2023-12-11 22:28:29,672] INFO _log() L187   * Restarting with stat - call_trace=C:\Users\Paula\AppData\Local\Programs\Python\Python311\Lib\site-packages\werkzeug\_internal.py L187 
[2023-12-11 22:29:21,750] INFO _log() L187  127.0.0.1 - - [11/Dec/2023 22:29:21] "GET /pessoas?person_id=5 HTTP/1.1" 200 - - call_trace=C:\Users\Paula\AppData\Local\Programs\Python\Python311\Lib\site-packages\werkzeug\_internal.py L187 
[2023-12-11 22:29:21,804] ERROR _finalize_fairy() L781  Exception during reset or similar - call_trace=C:\Users\Paula\AppData\Local\Programs\Python\Python311\Lib\site-packages\sqlalchemy\pool\base.py L781 
Traceback (most recent call last):
  File "C:\Users\Paula\AppData\Local\Programs\Python\Python311\Lib\site-packages\sqlalchemy\pool\base.py", line 753, in _finalize_fairy
    fairy._reset(pool)
  File "C:\Users\Paula\AppData\Local\Programs\Python\Python311\Lib\site-packages\sqlalchemy\pool\base.py", line 1004, in _reset
    pool._dialect.do_rollback(self)
  File "C:\Users\Paula\AppData\Local\Programs\Python\Python311\Lib\site-packages\sqlalchemy\engine\default.py", line 683, in do_rollback
    dbapi_connection.rollback()
sqlite3.ProgrammingError: SQLite objects created in a thread can only be used in that same thread. The object was created in thread id 20940 and this is thread id 28260.
[2023-12-11 22:29:21,808] ERROR _close_connection() L259  Exception closing connection <sqlite3.Connection object at 0x000001FAB68364D0> - call_trace=C:\Users\Paula\AppData\Local\Programs\Python\Python311\Lib\site-packages\sqlalchemy\pool\base.py L259 
Traceback (most recent call last):
  File "C:\Users\Paula\AppData\Local\Programs\Python\Python311\Lib\site-packages\sqlalchemy\pool\base.py", line 753, in _finalize_fairy
    fairy._reset(pool)
  File "C:\Users\Paula\AppData\Local\Programs\Python\Python311\Lib\site-packages\sqlalchemy\pool\base.py", line 1004, in _reset
    pool._dialect.do_rollback(self)
  File "C:\Users\Paula\AppData\Local\Programs\Python\Python311\Lib\site-packages\sqlalchemy\engine\default.py", line 683, in do_rollback
    dbapi_connection.rollback()
sqlite3.ProgrammingError: SQLite objects created in a thread can only be used in that same thread. The object was created in thread id 20940 and this is thread id 28260.

During handling of the above exception, another exception occurred:

Traceback (most recent call last):
  File "C:\Users\Paula\AppData\Local\Programs\Python\Python311\Lib\site-packages\sqlalchemy\pool\base.py", line 255, in _close_connection
    self._dialect.do_terminate(connection)
  File "C:\Users\Paula\AppData\Local\Programs\Python\Python311\Lib\site-packages\sqlalchemy\engine\default.py", line 689, in do_terminate
    self.do_close(dbapi_connection)
  File "C:\Users\Paula\AppData\Local\Programs\Python\Python311\Lib\site-packages\sqlalchemy\engine\default.py", line 692, in do_close
    dbapi_connection.close()
sqlite3.ProgrammingError: SQLite objects created in a thread can only be used in that same thread. The object was created in thread id 20940 and this is thread id 28260.
[2023-12-11 22:29:22,325] ERROR log_exception() L1741 Exception on /pessoa [POST] - call_trace=C:\Users\Paula\AppData\Local\Programs\Python\Python311\Lib\site-packages\flask\app.py L1741
Traceback (most recent call last):
  File "C:\Users\Paula\AppData\Local\Programs\Python\Python311\Lib\site-packages\flask\app.py", line 2525, in wsgi_app
    response = self.full_dispatch_request()
               ^^^^^^^^^^^^^^^^^^^^^^^^^^^^
  File "C:\Users\Paula\AppData\Local\Programs\Python\Python311\Lib\site-packages\flask\app.py", line 1822, in full_dispatch_request
    rv = self.handle_user_exception(e)
         ^^^^^^^^^^^^^^^^^^^^^^^^^^^^^
  File "C:\Users\Paula\AppData\Local\Programs\Python\Python311\Lib\site-packages\flask_cors\extension.py", line 176, in wrapped_function
    return cors_after_request(app.make_response(f(*args, **kwargs)))
                                                ^^^^^^^^^^^^^^^^^^
  File "C:\Users\Paula\AppData\Local\Programs\Python\Python311\Lib\site-packages\flask\app.py", line 1820, in full_dispatch_request
    rv = self.dispatch_request()
         ^^^^^^^^^^^^^^^^^^^^^^^
  File "C:\Users\Paula\AppData\Local\Programs\Python\Python311\Lib\site-packages\flask\app.py", line 1796, in dispatch_request
    return self.ensure_sync(self.view_functions[rule.endpoint])(**view_args)
           ^^^^^^^^^^^^^^^^^^^^^^^^^^^^^^^^^^^^^^^^^^^^^^^^^^^^^^^^^^^^^^^^^
  File "C:\Users\Paula\AppData\Local\Programs\Python\Python311\Lib\site-packages\flask_openapi3\scaffold.py", line 127, in view_func
    response = func(**func_kwargs)
               ^^^^^^^^^^^^^^^^^^^
  File "C:\Users\Paula\Documents\CURSOS\Pos Eng Software\Sprint 4\MVP\codigos\mvp_sleep_health\api\app.py", line 109, in predict
    outcome=Model.preditor(modelo, form),
            ^^^^^^^^^^^^^^^^^^^^^^^^^^^^
TypeError: Model.preditor() missing 1 required positional argument: 'form'
[2023-12-11 22:29:22,330] INFO _log() L187  127.0.0.1 - - [11/Dec/2023 22:29:22] "[35m[1mPOST /pessoa HTTP/1.1[0m" 500 - - call_trace=C:\Users\Paula\AppData\Local\Programs\Python\Python311\Lib\site-packages\werkzeug\_internal.py L187 
[2023-12-11 22:30:06,186] INFO _log() L187   * Detected change in 'C:\\Users\\Paula\\Documents\\CURSOS\\Pos Eng Software\\Sprint 4\\MVP\\codigos\\mvp_sleep_health\\api\\model\\modelo.py', reloading - call_trace=C:\Users\Paula\AppData\Local\Programs\Python\Python311\Lib\site-packages\werkzeug\_internal.py L187 
[2023-12-11 22:30:06,382] INFO _log() L187   * Restarting with stat - call_trace=C:\Users\Paula\AppData\Local\Programs\Python\Python311\Lib\site-packages\werkzeug\_internal.py L187 
[2023-12-11 22:30:15,970] INFO _log() L187   * Detected change in 'C:\\Users\\Paula\\Documents\\CURSOS\\Pos Eng Software\\Sprint 4\\MVP\\codigos\\mvp_sleep_health\\api\\model\\modelo.py', reloading - call_trace=C:\Users\Paula\AppData\Local\Programs\Python\Python311\Lib\site-packages\werkzeug\_internal.py L187 
[2023-12-11 22:30:16,110] INFO _log() L187   * Restarting with stat - call_trace=C:\Users\Paula\AppData\Local\Programs\Python\Python311\Lib\site-packages\werkzeug\_internal.py L187 
[2023-12-11 22:30:19,012] INFO _log() L187   * Detected change in 'C:\\Users\\Paula\\Documents\\CURSOS\\Pos Eng Software\\Sprint 4\\MVP\\codigos\\mvp_sleep_health\\api\\model\\modelo.py', reloading - call_trace=C:\Users\Paula\AppData\Local\Programs\Python\Python311\Lib\site-packages\werkzeug\_internal.py L187 
[2023-12-11 22:30:19,161] INFO _log() L187   * Restarting with stat - call_trace=C:\Users\Paula\AppData\Local\Programs\Python\Python311\Lib\site-packages\werkzeug\_internal.py L187 
[2023-12-11 22:30:29,163] INFO _log() L187  127.0.0.1 - - [11/Dec/2023 22:30:29] "GET /pessoas HTTP/1.1" 200 - - call_trace=C:\Users\Paula\AppData\Local\Programs\Python\Python311\Lib\site-packages\werkzeug\_internal.py L187 
[2023-12-11 22:30:43,413] INFO _log() L187  127.0.0.1 - - [11/Dec/2023 22:30:43] "GET /pessoas?person_id=5 HTTP/1.1" 200 - - call_trace=C:\Users\Paula\AppData\Local\Programs\Python\Python311\Lib\site-packages\werkzeug\_internal.py L187 
[2023-12-11 22:30:43,436] ERROR _finalize_fairy() L781  Exception during reset or similar - call_trace=C:\Users\Paula\AppData\Local\Programs\Python\Python311\Lib\site-packages\sqlalchemy\pool\base.py L781 
Traceback (most recent call last):
  File "<frozen importlib._bootstrap_external>", line 1437, in _path_importer_cache
KeyError: 'C:\\Users\\Paula\\AppData\\Local\\Programs\\Python\\Python311\\Lib\\site-packages\\sklearn'

During handling of the above exception, another exception occurred:

Traceback (most recent call last):
  File "C:\Users\Paula\AppData\Local\Programs\Python\Python311\Lib\site-packages\sqlalchemy\pool\base.py", line 753, in _finalize_fairy
    fairy._reset(pool)
  File "C:\Users\Paula\AppData\Local\Programs\Python\Python311\Lib\site-packages\sqlalchemy\pool\base.py", line 1004, in _reset
    pool._dialect.do_rollback(self)
  File "C:\Users\Paula\AppData\Local\Programs\Python\Python311\Lib\site-packages\sqlalchemy\engine\default.py", line 683, in do_rollback
    dbapi_connection.rollback()
sqlite3.ProgrammingError: SQLite objects created in a thread can only be used in that same thread. The object was created in thread id 12444 and this is thread id 26876.
[2023-12-11 22:30:43,522] ERROR _finalize_fairy() L781  Exception during reset or similar - call_trace=C:\Users\Paula\AppData\Local\Programs\Python\Python311\Lib\site-packages\sqlalchemy\pool\base.py L781 
Traceback (most recent call last):
  File "C:\Users\Paula\AppData\Local\Programs\Python\Python311\Lib\site-packages\sqlalchemy\pool\base.py", line 753, in _finalize_fairy
    fairy._reset(pool)
  File "C:\Users\Paula\AppData\Local\Programs\Python\Python311\Lib\site-packages\sqlalchemy\pool\base.py", line 1004, in _reset
    pool._dialect.do_rollback(self)
  File "C:\Users\Paula\AppData\Local\Programs\Python\Python311\Lib\site-packages\sqlalchemy\engine\default.py", line 683, in do_rollback
    dbapi_connection.rollback()
sqlite3.ProgrammingError: SQLite objects created in a thread can only be used in that same thread. The object was created in thread id 18020 and this is thread id 26876.
