[2023-12-11 22:23:33,142] INFO _log() L187   * Restarting with stat - call_trace=C:\Users\Paula\AppData\Local\Programs\Python\Python311\Lib\site-packages\werkzeug\_internal.py L187 
[2023-12-11 22:23:38,129] INFO _log() L187   * Detected change in 'C:\\Users\\Paula\\Documents\\CURSOS\\Pos Eng Software\\Sprint 4\\MVP\\codigos\\mvp_sleep_health\\api\\model\\modelo.py', reloading - call_trace=C:\Users\Paula\AppData\Local\Programs\Python\Python311\Lib\site-packages\werkzeug\_internal.py L187 
[2023-12-11 22:23:38,275] INFO _log() L187   * Restarting with stat - call_trace=C:\Users\Paula\AppData\Local\Programs\Python\Python311\Lib\site-packages\werkzeug\_internal.py L187 
[2023-12-11 22:23:47,344] INFO _log() L187   * Detected change in 'C:\\Users\\Paula\\Documents\\CURSOS\\Pos Eng Software\\Sprint 4\\MVP\\codigos\\mvp_sleep_health\\api\\model\\modelo.py', reloading - call_trace=C:\Users\Paula\AppData\Local\Programs\Python\Python311\Lib\site-packages\werkzeug\_internal.py L187 
[2023-12-11 22:23:47,482] INFO _log() L187   * Restarting with stat - call_trace=C:\Users\Paula\AppData\Local\Programs\Python\Python311\Lib\site-packages\werkzeug\_internal.py L187 
[2023-12-11 22:23:53,392] INFO _log() L187  127.0.0.1 - - [11/Dec/2023 22:23:53] "GET /pessoas HTTP/1.1" 200 - - call_trace=C:\Users\Paula\AppData\Local\Programs\Python\Python311\Lib\site-packages\werkzeug\_internal.py L187 
[2023-12-11 22:24:31,532] INFO _log() L187  127.0.0.1 - - [11/Dec/2023 22:24:31] "GET /pessoas?person_id=5 HTTP/1.1" 200 - - call_trace=C:\Users\Paula\AppData\Local\Programs\Python\Python311\Lib\site-packages\werkzeug\_internal.py L187 
[2023-12-11 22:24:31,546] ERROR _finalize_fairy() L781  Exception during reset or similar - call_trace=C:\Users\Paula\AppData\Local\Programs\Python\Python311\Lib\site-packages\sqlalchemy\pool\base.py L781 
Traceback (most recent call last):
  File "C:\Users\Paula\AppData\Local\Programs\Python\Python311\Lib\site-packages\sqlalchemy\pool\base.py", line 753, in _finalize_fairy
    fairy._reset(pool)
  File "C:\Users\Paula\AppData\Local\Programs\Python\Python311\Lib\site-packages\sqlalchemy\pool\base.py", line 1004, in _reset
    pool._dialect.do_rollback(self)
  File "C:\Users\Paula\AppData\Local\Programs\Python\Python311\Lib\site-packages\sqlalchemy\engine\default.py", line 683, in do_rollback
    dbapi_connection.rollback()
sqlite3.ProgrammingError: SQLite objects created in a thread can only be used in that same thread. The object was created in thread id 11972 and this is thread id 11556.
[2023-12-11 22:24:31,550] ERROR _close_connection() L259  Exception closing connection <sqlite3.Connection object at 0x0000021B7960C400> - call_trace=C:\Users\Paula\AppData\Local\Programs\Python\Python311\Lib\site-packages\sqlalchemy\pool\base.py L259 
Traceback (most recent call last):
  File "C:\Users\Paula\AppData\Local\Programs\Python\Python311\Lib\site-packages\sqlalchemy\pool\base.py", line 753, in _finalize_fairy
    fairy._reset(pool)
  File "C:\Users\Paula\AppData\Local\Programs\Python\Python311\Lib\site-packages\sqlalchemy\pool\base.py", line 1004, in _reset
    pool._dialect.do_rollback(self)
  File "C:\Users\Paula\AppData\Local\Programs\Python\Python311\Lib\site-packages\sqlalchemy\engine\default.py", line 683, in do_rollback
    dbapi_connection.rollback()
sqlite3.ProgrammingError: SQLite objects created in a thread can only be used in that same thread. The object was created in thread id 11972 and this is thread id 11556.

During handling of the above exception, another exception occurred:

Traceback (most recent call last):
  File "C:\Users\Paula\AppData\Local\Programs\Python\Python311\Lib\site-packages\sqlalchemy\pool\base.py", line 255, in _close_connection
    self._dialect.do_terminate(connection)
  File "C:\Users\Paula\AppData\Local\Programs\Python\Python311\Lib\site-packages\sqlalchemy\engine\default.py", line 689, in do_terminate
    self.do_close(dbapi_connection)
  File "C:\Users\Paula\AppData\Local\Programs\Python\Python311\Lib\site-packages\sqlalchemy\engine\default.py", line 692, in do_close
    dbapi_connection.close()
sqlite3.ProgrammingError: SQLite objects created in a thread can only be used in that same thread. The object was created in thread id 11972 and this is thread id 11556.
[2023-12-11 22:24:31,597] ERROR _finalize_fairy() L781  Exception during reset or similar - call_trace=C:\Users\Paula\AppData\Local\Programs\Python\Python311\Lib\site-packages\sqlalchemy\pool\base.py L781 
Traceback (most recent call last):
  File "C:\Users\Paula\AppData\Local\Programs\Python\Python311\Lib\site-packages\sqlalchemy\pool\base.py", line 753, in _finalize_fairy
    fairy._reset(pool)
  File "C:\Users\Paula\AppData\Local\Programs\Python\Python311\Lib\site-packages\sqlalchemy\pool\base.py", line 1004, in _reset
    pool._dialect.do_rollback(self)
  File "C:\Users\Paula\AppData\Local\Programs\Python\Python311\Lib\site-packages\sqlalchemy\engine\default.py", line 683, in do_rollback
    dbapi_connection.rollback()
sqlite3.ProgrammingError: SQLite objects created in a thread can only be used in that same thread. The object was created in thread id 3860 and this is thread id 11556.
[2023-12-11 22:24:31,599] ERROR _close_connection() L259  Exception closing connection <sqlite3.Connection object at 0x0000021B796C24D0> - call_trace=C:\Users\Paula\AppData\Local\Programs\Python\Python311\Lib\site-packages\sqlalchemy\pool\base.py L259 
Traceback (most recent call last):
  File "C:\Users\Paula\AppData\Local\Programs\Python\Python311\Lib\site-packages\sqlalchemy\pool\base.py", line 753, in _finalize_fairy
    fairy._reset(pool)
  File "C:\Users\Paula\AppData\Local\Programs\Python\Python311\Lib\site-packages\sqlalchemy\pool\base.py", line 1004, in _reset
    pool._dialect.do_rollback(self)
  File "C:\Users\Paula\AppData\Local\Programs\Python\Python311\Lib\site-packages\sqlalchemy\engine\default.py", line 683, in do_rollback
    dbapi_connection.rollback()
sqlite3.ProgrammingError: SQLite objects created in a thread can only be used in that same thread. The object was created in thread id 3860 and this is thread id 11556.

During handling of the above exception, another exception occurred:

Traceback (most recent call last):
  File "C:\Users\Paula\AppData\Local\Programs\Python\Python311\Lib\site-packages\sqlalchemy\pool\base.py", line 255, in _close_connection
    self._dialect.do_terminate(connection)
  File "C:\Users\Paula\AppData\Local\Programs\Python\Python311\Lib\site-packages\sqlalchemy\engine\default.py", line 689, in do_terminate
    self.do_close(dbapi_connection)
  File "C:\Users\Paula\AppData\Local\Programs\Python\Python311\Lib\site-packages\sqlalchemy\engine\default.py", line 692, in do_close
    dbapi_connection.close()
sqlite3.ProgrammingError: SQLite objects created in a thread can only be used in that same thread. The object was created in thread id 3860 and this is thread id 11556.
[2023-12-11 22:24:32,063] ERROR log_exception() L1741 Exception on /pessoa [POST] - call_trace=C:\Users\Paula\AppData\Local\Programs\Python\Python311\Lib\site-packages\flask\app.py L1741
Traceback (most recent call last):
  File "C:\Users\Paula\AppData\Local\Programs\Python\Python311\Lib\site-packages\flask\app.py", line 2525, in wsgi_app
    response = self.full_dispatch_request()
               ^^^^^^^^^^^^^^^^^^^^^^^^^^^^
  File "C:\Users\Paula\AppData\Local\Programs\Python\Python311\Lib\site-packages\flask\app.py", line 1822, in full_dispatch_request
    rv = self.handle_user_exception(e)
         ^^^^^^^^^^^^^^^^^^^^^^^^^^^^^
  File "C:\Users\Paula\AppData\Local\Programs\Python\Python311\Lib\site-packages\flask_cors\extension.py", line 176, in wrapped_function
    return cors_after_request(app.make_response(f(*args, **kwargs)))
                                                ^^^^^^^^^^^^^^^^^^
  File "C:\Users\Paula\AppData\Local\Programs\Python\Python311\Lib\site-packages\flask\app.py", line 1820, in full_dispatch_request
    rv = self.dispatch_request()
         ^^^^^^^^^^^^^^^^^^^^^^^
  File "C:\Users\Paula\AppData\Local\Programs\Python\Python311\Lib\site-packages\flask\app.py", line 1796, in dispatch_request
    return self.ensure_sync(self.view_functions[rule.endpoint])(**view_args)
           ^^^^^^^^^^^^^^^^^^^^^^^^^^^^^^^^^^^^^^^^^^^^^^^^^^^^^^^^^^^^^^^^^
  File "C:\Users\Paula\AppData\Local\Programs\Python\Python311\Lib\site-packages\flask_openapi3\scaffold.py", line 127, in view_func
    response = func(**func_kwargs)
               ^^^^^^^^^^^^^^^^^^^
  File "C:\Users\Paula\Documents\CURSOS\Pos Eng Software\Sprint 4\MVP\codigos\mvp_sleep_health\api\app.py", line 95, in predict
    modelo = Model.carrega_modelo(ml_path, scaler)
             ^^^^^^^^^^^^^^^^^^^^^^^^^^^^^^^^^^^^^
  File "C:\Users\Paula\Documents\CURSOS\Pos Eng Software\Sprint 4\MVP\codigos\mvp_sleep_health\api\model\modelo.py", line 11, in carrega_modelo
    if path.endswith(".pkl"):
       ^^^^^^^^^^^^^
AttributeError: 'StandardScaler' object has no attribute 'endswith'
[2023-12-11 22:24:32,068] INFO _log() L187  127.0.0.1 - - [11/Dec/2023 22:24:32] "[35m[1mPOST /pessoa HTTP/1.1[0m" 500 - - call_trace=C:\Users\Paula\AppData\Local\Programs\Python\Python311\Lib\site-packages\werkzeug\_internal.py L187 
[2023-12-11 22:25:41,393] INFO _log() L187   * Detected change in 'C:\\Users\\Paula\\Documents\\CURSOS\\Pos Eng Software\\Sprint 4\\MVP\\codigos\\mvp_sleep_health\\api\\model\\modelo.py', reloading - call_trace=C:\Users\Paula\AppData\Local\Programs\Python\Python311\Lib\site-packages\werkzeug\_internal.py L187 
[2023-12-11 22:25:41,584] INFO _log() L187   * Restarting with stat - call_trace=C:\Users\Paula\AppData\Local\Programs\Python\Python311\Lib\site-packages\werkzeug\_internal.py L187 
